<?xml version="1.0" encoding="utf-8"?>
<!--SPDX-License-Identifier: Apache-2.0-->
<robot name="mikrik"
	xmlns:xacro="http://www.ros.org/wiki/xacro">
	<!-- left_wheel_geometry -->
	<link name="left_wheel">
		<visual>
			<origin xyz="0 0 0" rpy="${PI/2} 0 0" />
			<geometry>
				<cylinder length="${wheel_width}" radius="${wheel_radius}"/>
			</geometry>
			<material name="Green" />
		</visual>
		<collision>
			<origin xyz="0 0 0" rpy="${PI/2} 0 0" />
			<geometry>
				<cylinder length="${wheel_width}" radius="${wheel_radius}"/>
			</geometry>
		</collision>
	</link>
	<joint name="left_wheel_to_base" type="continuous">
		<origin xyz="0 0.068 0.0145" rpy="0 0 0" />
		<parent link="mikrik_base" />
		<child link="left_wheel" />
		<axis xyz="0 1 0" />
	</joint>
</robot>
